Workbook
Name Slicer_Year: #N/A

Sheet pivot table
A3: Row Labels | B3: Sum of Net Sales | D3: Row Labels | E3: Sum of Net Sales | G3: Row Labels | H3: Sum of Profit/loss | J3: Row Labels | K3: Sum of Net Sales | M3: Row Labels | N3: Sum of OrderQuantity | P3: Row Labels | Q3: Count of Feedback Category
A4: 2026 | B4: 372154.52 | D4: Africa | E4: 241857.84 | G4: Asia | H4: 112686.62 | J4: Liam Chen | K4: 44339.168 | M4: Smartwatch | N4: 723 | P4: Negative | Q4: 36
A5: 2025 | B5: 297186.69 | D5: Europe | E5: 252958.85 | G5: North America | H5: 98944.172 | J5: Carlos Rodriguez | K5: 78765.721 | M5: Laptop | N5: 679 | P5: Neutral | Q5: 127
A6: 2024 | B6: 301306.01 | D6: North America | E6: 253644.17 | G6: Africa | H6: 93057.838 | J6: Emma Dubois | K6: 96946.052 | M6: Headphones | N6: 662 | P6: Postive | Q6: 271
A7: 2023 | B7: 361224.4 | D7: South America | E7: 274724.13 | G7: South America | H7: 85674.126 | J7: Olivia Patel | K7: 97540.157 | M7: Tablet | N7: 650 | P7: Grand Total | Q7: 434
A8: Grand Total | B8: 1331871.6 | D8: Asia | E8: 308686.62 | G8: Europe | H8: 74158.853 | J8: Noah Kim | K8: 98415.381 | M8: Smartphone | N8: 628
D9: Grand Total | E9: 1331871.6 | G9: Grand Total | H9: 464521.61 | J9: Ahmed Khan | K9: 194539.21 | M9: Grand Total | N9: 3342
J10: Fatima Adebayo | K10: 199117.3
J11: Maria Garcia | K11: 246447.65
J12: Sophie Lee | K12: 275760.96
J13: Grand Total | K13: 1331871.6

Sheet Sales Dataset
A1: OrderID | B1: CustomerID | C1: SalesRepID | D1: SalesRepName | E1: Date | F1: Year | G1: Month | H1: Day | I1: Time | J1: Hour | K1: Minute | L1: Product | M1: Product cat | N1: OrderQuantity | O1: UnitPrice | P1: Unit Cost | Q1: Region | R1: SalesRepEmail | S1: Feedback | T1: Feedback Category | U1: Gross Revenue | V1: Total Cost | W1: Tax Rate | X1: Tax Amount | Y1: Discount Rate | Z1: Discount Amount | AA1: Net Sales | AB1: Profit/loss
A2: ORD-00001 | B2: CUST-754 | C2: REP-13 | D2: Ahmed Khan | E2: 45490 | F2: =YEAR(E2) -> 2024 | G2: =TEXT(E2,"mmmm") -> July | H2: =TEXT(E2, "dddd") -> Wednesday | I2: 0.46443287 | J2: =HOUR(I2) -> 11 | K2: =MINUTE(I2) -> 8 | L2: Laptop | M2: Computers | N2: 15 | O2: 1095.25 | P2: =VLOOKUP(L2,'Product-cost'!A:B,2,FALSE) -> 600 | Q2: North America | R2: ahmedkhan@tg.inc | S2: Excellent quality | T2: Postive | U2: =O2*N2 -> 16428.75 | V2: =P2*N2 -> 9000 | W2: =VLOOKUP(Q2,Taxrate!A:B,2,FALSE) -> 0.07 | X2: =U2*W2 -> 1150.0125 | Y2: =VLOOKUP(L2,'Discount Rate'!A:B,2,FALSE) -> 0.05 | Z2: =Y2*U2 -> 821.4375 | AA2: =U2-X2-Z2 -> 14457.3 | AB2: =AA2-V2 -> 5457.3
A3: ORD-00002 | B3: CUST-529 | C3: REP-17 | D3: Maria Garcia | E3: 46133 | F3: =YEAR(E3) -> 2026 | G3: =TEXT(E3,"mmmm") -> April | H3: =TEXT(E3, "dddd") -> Tuesday | I3: 0.87152778 | J3: =HOUR(I3) -> 20 | K3: =MINUTE(I3) -> 55 | L3: Smartphone | M3: Mobile Devices | N3: 6 | O3: 544.59 | P3: =VLOOKUP(L3,'Product-cost'!A:B,2,FALSE) -> 300 | Q3: Asia | R3: mariagarcia@tg.inc | S3: Fast delivery | T3: Postive | U3: =O3*N3 -> 3267.54 | V3: =P3*N3 -> 1800 | W3: =VLOOKUP(Q3,Taxrate!A:B,2,FALSE) -> 0.1 | X3: =U3*W3 -> 326.754 | Y3: =VLOOKUP(L3,'Discount Rate'!A:B,2,FALSE) -> 0.1 | Z3: =Y3*U3 -> 326.754 | AA3: =U3-X3-Z3 -> 2614.032 | AB3: =AA3-V3 -> 814.032
A4: ORD-00003 | B4: CUST-649 | C4: REP-13 | D4: Ahmed Khan | E4: 45236 | F4: =YEAR(E4) -> 2023 | G4: =TEXT(E4,"mmmm") -> November | H4: =TEXT(E4, "dddd") -> Monday | I4: 0.90322917 | J4: =HOUR(I4) -> 21 | K4: =MINUTE(I4) -> 40 | L4: Tablet | M4: Tablets | N4: 12 | O4: 500 | P4: =VLOOKUP(L4,'Product-cost'!A:B,2,FALSE) -> 200 | Q4: Europe | R4: ahmedkhan@sales.techg.com | S4: Good value for money | T4: Postive | U4: =O4*N4 -> 6000 | V4: =P4*N4 -> 2400 | W4: =VLOOKUP(Q4,Taxrate!A:B,2,FALSE) -> 0.2 | X4: =U4*W4 -> 1200 | Y4: =VLOOKUP(L4,'Discount Rate'!A:B,2,FALSE) -> 0.08 | Z4: =Y4*U4 -> 480 | AA4: =U4-X4-Z4 -> 4320 | AB4: =AA4-V4 -> 1920
A5: ORD-00004 | B5: CUST-266 | C5: REP-22 | D5: Fatima Adebayo | E5: 45415 | F5: =YEAR(E5) -> 2024 | G5: =TEXT(E5,"mmmm") -> May | H5: =TEXT(E5, "dddd") -> Friday | I5: 0.83313657 | J5: =HOUR(I5) -> 19 | K5: =MINUTE(I5) -> 59 | L5: Laptop | M5: Computers | N5: 3 | O5: 922.41 | P5: =VLOOKUP(L5,'Product-cost'!A:B,2,FALSE) -> 600 | Q5: South America | R5: fatimaadebayo@sales.techg.com | S5: Very satisfied | T5: Postive | U5: =O5*N5 -> 2767.23 | V5: =P5*N5 -> 1800 | W5: =VLOOKUP(Q5,Taxrate!A:B,2,FALSE) -> 0.15 | X5: =U5*W5 -> 415.0845 | Y5: =VLOOKUP(L5,'Discount Rate'!A:B,2,FALSE) -> 0.05 | Z5: =Y5*U5 -> 138.3615 | AA5: =U5-X5-Z5 -> 2213.784 | AB5: =AA5-V5 -> 413.784
A6: ORD-00005 | B6: CUST-334 | C6: REP-11 | D6: Emma Dubois | E6: 45661 | F6: =YEAR(E6) -> 2025 | G6: =TEXT(E6,"mmmm") -> January | H6: =TEXT(E6, "dddd") -> Saturday | I6: 0.38469907 | J6: =HOUR(I6) -> 9 | K6: =MINUTE(I6) -> 13 | L6: Smartwatch | M6: Wearables | N6: 6 | O6: 230.92 | P6: =VLOOKUP(L6,'Product-cost'!A:B,2,FALSE) -> 150 | Q6: South America | R6: emmadubois@techgadgetsco.com | T6: Neutral | U6: =O6*N6 -> 1385.52 | V6: =P6*N6 -> 900 | W6: =VLOOKUP(Q6,Taxrate!A:B,2,FALSE) -> 0.15 | X6: =U6*W6 -> 207.828 | Y6: =VLOOKUP(L6,'Discount Rate'!A:B,2,FALSE) -> 0.07 | Z6: =Y6*U6 -> 96.9864 | AA6: =U6-X6-Z6 -> 1080.7056 | AB6: =AA6-V6 -> 180.7056
A7: ORD-00006 | B7: CUST-470 | C7: REP-17 | D7: Maria Garcia | E7: 45911 | F7: =YEAR(E7) -> 2025 | G7: =TEXT(E7,"mmmm") -> September | H7: =TEXT(E7, "dddd") -> Thursday | I7: 0.40836806 | J7: =HOUR(I7) -> 9 | K7: =MINUTE(I7) -> 48 | L7: Laptop | M7: Computers | N7: 3 | O7: 1011.08 | P7: =VLOOKUP(L7,'Product-cost'!A:B,2,FALSE) -> 600 | Q7: North America | R7: mariagarcia@techgadgetsco.com | T7: Neutral | U7: =O7*N7 -> 3033.24 | V7: =P7*N7 -> 1800 | W7: =VLOOKUP(Q7,Taxrate!A:B,2,FALSE) -> 0.07 | X7: =U7*W7 -> 212.3268 | Y7: =VLOOKUP(L7,'Discount Rate'!A:B,2,FALSE) -> 0.05 | Z7: =Y7*U7 -> 151.662 | AA7: =U7-X7-Z7 -> 2669.2512 | AB7: =AA7-V7 -> 869.2512
A8: ORD-00007 | B8: CUST-838 | C8: REP-13 | D8: Ahmed Khan | E8: 46150 | F8: =YEAR(E8) -> 2026 | G8: =TEXT(E8,"mmmm") -> May | H8: =TEXT(E8, "dddd") -> Friday | I8: 0.3878125 | J8: =HOUR(I8) -> 9 | K8: =MINUTE(I8) -> 18 | L8: Smartphone | M8: Mobile Devices | N8: 12 | O8: 559.02 | P8: =VLOOKUP(L8,'Product-cost'!A:B,2,FALSE) -> 300 | Q8: Africa | R8: ahmedkhan@sales.techg.com | T8: Neutral | U8: =O8*N8 -> 6708.24 | V8: =P8*N8 -> 3600 | W8: =VLOOKUP(Q8,Taxrate!A:B,2,FALSE) -> 0.12 | X8: =U8*W8 -> 804.9888 | Y8: =VLOOKUP(L8,'Discount Rate'!A:B,2,FALSE) -> 0.1 | Z8: =Y8*U8 -> 670.824 | AA8: =U8-X8-Z8 -> 5232.4272 | AB8: =AA8-V8 -> 1632.4272
A9: ORD-00008 | B9: CUST-482 | C9: REP-15 | D9: Sophie Lee | E9: 46013 | F9: =YEAR(E9) -> 2025 | G9: =TEXT(E9,"mmmm") -> December | H9: =TEXT(E9, "dddd") -> Monday | I9: 0.72258102 | J9: =HOUR(I9) -> 17 | K9: =MINUTE(I9) -> 20 | L9: Laptop | M9: Computers | N9: 6 | O9: 1215.83 | P9: =VLOOKUP(L9,'Product-cost'!A:B,2,FALSE) -> 600 | Q9: Asia | R9: sophielee@sales.techg.com | T9: Neutral | U9: =O9*N9 -> 7294.98 | V9: =P9*N9 -> 3600 | W9: =VLOOKUP(Q9,Taxrate!A:B,2,FALSE) -> 0.1 | X9: =U9*W9 -> 729.498 | Y9: =VLOOKUP(L9,'Discount Rate'!A:B,2,FALSE) -> 0.05 | Z9: =Y9*U9 -> 364.749 | AA9: =U9-X9-Z9 -> 6200.733 | AB9: =AA9-V9 -> 2600.733
A10: ORD-00009 | B10: CUST-878 | C10: REP-33 | D10: Ahmed Khan | E10: 45189 | F10: =YEAR(E10) -> 2023 | G10: =TEXT(E10,"mmmm") -> September | H10: =TEXT(E10, "dddd") -> Wednesday | I10: 0.6737963 | J10: =HOUR(I10) -> 16 | K10: =MINUTE(I10) -> 10 | L10: Smartwatch | M10: Wearables | N10: 7 | O10: 278.18 | P10: =VLOOKUP(L10,'Product-cost'!A:B,2,FALSE) -> 150 | Q10: Europe | R10: ahmedkhan@sales.techg.com | S10: Fast delivery | T10: Postive | U10: =O10*N10 -> 1947.26 | V10: =P10*N10 -> 1050 | W10: =VLOOKUP(Q10,Taxrate!A:B,2,FALSE) -> 0.2 | X10: =U10*W10 -> 389.452 | Y10: =VLOOKUP(L10,'Discount Rate'!A:B,2,FALSE) -> 0.07 | Z10: =Y10*U10 -> 136.3082 | AA10: =U10-X10-Z10 -> 1421.4998 | AB10: =AA10-V10 -> 371.4998
A11: ORD-00010 | B11: CUST-330 | C11: REP-12 | D11: Olivia Patel | E11: 44970 | F11: =YEAR(E11) -> 2023 | G11: =TEXT(E11,"mmmm") -> February | H11: =TEXT(E11, "dddd") -> Monday | I11: 0.71805556 | J11: =HOUR(I11) -> 17 | K11: =MINUTE(I11) -> 14 | L11: Laptop | M11: Computers | N11: 1 | O11: 1252.71 | P11: =VLOOKUP(L11,'Product-cost'!A:B,2,FALSE) -> 600 | Q11: Asia | R11: oliviapatel@tg.inc | S11: Packaging was damaged | T11: Negative | U11: =O11*N11 -> 1252.71 | V11: =P11*N11 -> 600 | W11: =VLOOKUP(Q11,Taxrate!A:B,2,FALSE) -> 0.1 | X11: =U11*W11 -> 125.271 | Y11: =VLOOKUP(L11,'Discount Rate'!A:B,2,FALSE) -> 0.05 | Z11: =Y11*U11 -> 62.6355 | AA11: =U11-X11-Z11 -> 1064.8035 | AB11: =AA11-V11 -> 464.8035
A12: ORD-00011 | B12: CUST-690 | C12: REP-29 | D12: Sophie Lee | E12: 45895 | F12: =YEAR(E12) -> 2025 | G12: =TEXT(E12,"mmmm") -> August | H12: =TEXT(E12, "dddd") -> Tuesday | I12: 0.46256944 | J12: =HOUR(I12) -> 11 | K12: =MINUTE(I12) -> 6 | L12: Headphones | M12: Audio | N12: 7 | O12: 174.68 | P12: =VLOOKUP(L12,'Product-cost'!A:B,2,FALSE) -> 50 | Q12: North America | R12: sophielee@tg.inc | S12: Good value for money | T12: Postive | U12: =O12*N12 -> 1222.76 | V12: =P12*N12 -> 350 | W12: =VLOOKUP(Q12,Taxrate!A:B,2,FALSE) -> 0.07 | X12: =U12*W12 -> 85.5932 | Y12: =VLOOKUP(L12,'Discount Rate'!A:B,2,FALSE) -> 0.03 | Z12: =Y12*U12 -> 36.6828 | AA12: =U12-X12-Z12 -> 1100.484 | AB12: =AA12-V12 -> 750.484
A13: ORD-00012 | B13: CUST-532 | C13: REP-15 | D13: Sophie Lee | E13: 45785 | F13: =YEAR(E13) -> 2025 | G13: =TEXT(E13,"mmmm") -> May | H13: =TEXT(E13, "dddd") -> Thursday | I13: 0.91601852 | J13: =HOUR(I13) -> 21 | K13: =MINUTE(I13) -> 59 | L13: Headphones | M13: Audio | N13: 14 | O13: 123.79 | P13: =VLOOKUP(L13,'Product-cost'!A:B,2,FALSE) -> 50 | Q13: Africa | R13: sophielee@tg.inc | S13: Very satisfied | T13: Postive | U13: =O13*N13 -> 1733.06 | V13: =P13*N13 -> 700 | W13: =VLOOKUP(Q13,Taxrate!A:B,2,FALSE) -> 0.12 | X13: =U13*W13 -> 207.9672 | Y13: =VLOOKUP(L13,'Discount Rate'!A:B,2,FALSE) -> 0.03 | Z13: =Y13*U13 -> 51.9918 | AA13: =U13-X13-Z13 -> 1473.101 | AB13: =AA13-V13 -> 773.101
A14: ORD-00013 | B14: CUST-510 | C14: REP-11 | D14: Emma Dubois | E14: 45703 | F14: =YEAR(E14) -> 2025 | G14: =TEXT(E14,"mmmm") -> February | H14: =TEXT(E14, "dddd") -> Saturday | I14: 0.59512731 | J14: =HOUR(I14) -> 14 | K14: =MINUTE(I14) -> 16 | L14: Headphones | M14: Audio | N14: 12 | O14: 194.66 | P14: =VLOOKUP(L14,'Product-cost'!A:B,2,FALSE) -> 50 | Q14: Africa | R14: emmadubois@tg.inc | S14: Packaging was damaged | T14: Negative | U14: =O14*N14 -> 2335.92 | V14: =P14*N14 -> 600 | W14: =VLOOKUP(Q14,Taxrate!A:B,2,FALSE) -> 0.12 | X14: =U14*W14 -> 280.3104 | Y14: =VLOOKUP(L14,'Discount Rate'!A:B,2,FALSE) -> 0.03 | Z14: =Y14*U14 -> 70.0776 | AA14: =U14-X14-Z14 -> 1985.532 | AB14: =AA14-V14 -> 1385.532
A15: ORD-00014 | B15: CUST-865 | C15: REP-21 | D15: Fatima Adebayo | E15: 45029 | F15: =YEAR(E15) -> 2023 | G15: =TEXT(E15,"mmmm") -> April | H15: =TEXT(E15, "dddd") -> Thursday | I15: 0.70756944 | J15: =HOUR(I15) -> 16 | K15: =MINUTE(I15) -> 58 | L15: Smartwatch | M15: Wearables | N15: 9 | O15: 500 | P15: =VLOOKUP(L15,'Product-cost'!A:B,2,FALSE) -> 150 | Q15: Europe | R15: fatimaadebayo@tg.inc | T15: Neutral | U15: =O15*N15 -> 4500 | V15: =P15*N15 -> 1350 | W15: =VLOOKUP(Q15,Taxrate!A:B,2,FALSE) -> 0.2 | X15: =U15*W15 -> 900 | Y15: =VLOOKUP(L15,'Discount Rate'!A:B,2,FALSE) -> 0.07 | Z15: =Y15*U15 -> 315 | AA15: =U15-X15-Z15 -> 3285 | AB15: =AA15-V15 -> 1935
A16: ORD-00015 | B16: CUST-708 | C16: REP-11 | D16: Emma Dubois | E16: 45094 | F16: =YEAR(E16) -> 2023 | G16: =TEXT(E16,"mmmm") -> June | H16: =TEXT(E16, "dddd") -> Saturday | I16: 0.77611111 | J16: =HOUR(I16) -> 18 | K16: =MINUTE(I16) -> 37 | L16: Smartwatch | M16: Wearables | N16: 5 | O16: 254.78 | P16: =VLOOKUP(L16,'Product-cost'!A:B,2,FALSE) -> 150 | Q16: Europe | R16: emmadubois@sales.techg.com | S16: Perfect fit | T16: Postive | U16: =O16*N16 -> 1273.9 | V16: =P16*N16 -> 750 | W16: =VLOOKUP(Q16,Taxrate!A:B,2,FALSE) -> 0.2 | X16: =U16*W16 -> 254.78 | Y16: =VLOOKUP(L16,'Discount Rate'!A:B,2,FALSE) -> 0.07 | Z16: =Y16*U16 -> 89.173 | AA16: =U16-X16-Z16 -> 929.947 | AB16: =AA16-V16 -> 179.947
A17: ORD-00016 | B17: CUST-569 | C17: REP-35 | D17: Carlos Rodriguez | E17: 45131 | F17: =YEAR(E17) -> 2023 | G17: =TEXT(E17,"mmmm") -> July | H17: =TEXT(E17, "dddd") -> Monday | I17: 0.67606481 | J17: =HOUR(I17) -> 16 | K17: =MINUTE(I17) -> 13 | L17: Tablet | M17: Tablets | N17: 6 | O17: 495.85 | P17: =VLOOKUP(L17,'Product-cost'!A:B,2,FALSE) -> 200 | Q17: Asia | R17: carlosrodriguez@tg.inc | T17: Neutral | U17: =O17*N17 -> 2975.1 | V17: =P17*N17 -> 1200 | W17: =VLOOKUP(Q17,Taxrate!A:B,2,FALSE) -> 0.1 | X17: =U17*W17 -> 297.51 | Y17: =VLOOKUP(L17,'Discount Rate'!A:B,2,FALSE) -> 0.08 | Z17: =Y17*U17 -> 238.008 | AA17: =U17-X17-Z17 -> 2439.582 | AB17: =AA17-V17 -> 1239.582
A18: ORD-00017 | B18: CUST-108 | C18: REP-33 | D18: Ahmed Khan | E18: 46285 | F18: =YEAR(E18) -> 2026 | G18: =TEXT(E18,"mmmm") -> September | H18: =TEXT(E18, "dddd") -> Sunday | I18: 0.4278588 | J18: =HOUR(I18) -> 10 | K18: =MINUTE(I18) -> 16 | L18: Laptop | M18: Computers | N18: 3 | O18: 1102.41 | P18: =VLOOKUP(L18,'Product-cost'!A:B,2,FALSE) -> 600 | Q18: Asia | R18: ahmedkhan@tg.inc | S18: Battery life amazing | T18: Postive | U18: =O18*N18 -> 3307.23 | V18: =P18*N18 -> 1800 | W18: =VLOOKUP(Q18,Taxrate!A:B,2,FALSE) -> 0.1 | X18: =U18*W18 -> 330.723 | Y18: =VLOOKUP(L18,'Discount Rate'!A:B,2,FALSE) -> 0.05 | Z18: =Y18*U18 -> 165.3615 | AA18: =U18-X18-Z18 -> 2811.1455 | AB18: =AA18-V18 -> 1011.1455
A19: ORD-00018 | B19: CUST-749 | C19: REP-24 | D19: Liam Chen | E19: 44930 | F19: =YEAR(E19) -> 2023 | G19: =TEXT(E19,"mmmm") -> January | H19: =TEXT(E19, "dddd") -> Wednesday | I19: 0.57578704 | J19: =HOUR(I19) -> 13 | K19: =MINUTE(I19) -> 49 | L19: Tablet | M19: Tablets | N19: 8 | O19: 405.54 | P19: =VLOOKUP(L19,'Product-cost'!A:B,2,FALSE) -> 200 | Q19: North America | R19: liamchen@sales.techg.com | S19: A bit expensive but worth it | T19: Neutral | U19: =O19*N19 -> 3244.32 | V19: =P19*N19 -> 1600 | W19: =VLOOKUP(Q19,Taxrate!A:B,2,FALSE) -> 0.07 | X19: =U19*W19 -> 227.1024 | Y19: =VLOOKUP(L19,'Discount Rate'!A:B,2,FALSE) -> 0.08 | Z19: =Y19*U19 -> 259.5456 | AA19: =U19-X19-Z19 -> 2757.672 | AB19: =AA19-V19 -> 1157.672
A20: ORD-00019 | B20: CUST-251 | C20: REP-24 | D20: Liam Chen | E20: 45012 | F20: =YEAR(E20) -> 2023 | G20: =TEXT(E20,"mmmm") -> March | H20: =TEXT(E20, "dddd") -> Monday | I20: 0.58193287 | J20: =HOUR(I20) -> 13 | K20: =MINUTE(I20) -> 57 | L20: Laptop | M20: Computers | N20: 4 | O20: 1133.47 | P20: =VLOOKUP(L20,'Product-cost'!A:B,2,FALSE) -> 600 | Q20: Asia | R20: liamchen@techgadgetsco.com | S20: A bit expensive but worth it | T20: Neutral | U20: =O20*N20 -> 4533.88 | V20: =P20*N20 -> 2400 | W20: =VLOOKUP(Q20,Taxrate!A:B,2,FALSE) -> 0.1 | X20: =U20*W20 -> 453.388 | Y20: =VLOOKUP(L20,'Discount Rate'!A:B,2,FALSE) -> 0.05 | Z20: =Y20*U20 -> 226.694 | AA20: =U20-X20-Z20 -> 3853.798 | AB20: =AA20-V20 -> 1453.798
A21: ORD-00020 | B21: CUST-919 | C21: REP-15 | D21: Sophie Lee | E21: 44977 | F21: =YEAR(E21) -> 2023 | G21: =TEXT(E21,"mmmm") -> February | H21: =TEXT(E21, "dddd") -> Monday | I21: 0.83288194 | J21: =HOUR(I21) -> 19 | K21: =MINUTE(I21) -> 59 | L21: Headphones | M21: Audio | N21: 14 | O21: 138.61 | P21: =VLOOKUP(L21,'Product-cost'!A:B,2,FALSE) -> 50 | Q21: Europe | R21: sophielee@tg.inc | S21: Battery life amazing | T21: Postive | U21: =O21*N21 -> 1940.54 | V21: =P21*N21 -> 700 | W21: =VLOOKUP(Q21,Taxrate!A:B,2,FALSE) -> 0.2 | X21: =U21*W21 -> 388.108 | Y21: =VLOOKUP(L21,'Discount Rate'!A:B,2,FALSE) -> 0.03 | Z21: =Y21*U21 -> 58.2162 | AA21: =U21-X21-Z21 -> 1494.2158 | AB21: =AA21-V21 -> 794.2158
A22: ORD-00021 | B22: CUST-412 | C22: REP-17 | D22: Maria Garcia | E22: 44975 | F22: =YEAR(E22) -> 2023 | G22: =TEXT(E22,"mmmm") -> February | H22: =TEXT(E22, "dddd") -> Saturday | I22: 0.59811343 | J22: =HOUR(I22) -> 14 | K22: =MINUTE(I22) -> 21 | L22: Laptop | M22: Computers | N22: 5 | O22: 1054.7 | P22: =VLOOKUP(L22,'Product-cost'!A:B,2,FALSE) -> 600 | Q22: Africa | R22: mariagarcia@techgadgetsco.com | T22: Neutral | U22: =O22*N22 -> 5273.5 | V22: =P22*N22 -> 3000 | W22: =VLOOKUP(Q22,Taxrate!A:B,2,FALSE) -> 0.12 | X22: =U22*W22 -> 632.82 | Y22: =VLOOKUP(L22,'Discount Rate'!A:B,2,FALSE) -> 0.05 | Z22: =Y22*U22 -> 263.675 | AA22: =U22-X22-Z22 -> 4377.005 | AB22: =AA22-V22 -> 1377.005
A23: ORD-00022 | B23: CUST-211 | C23: REP-35 | D23: Carlos Rodriguez | E23: 45516 | F23: =YEAR(E23) -> 2024 | G23: =TEXT(E23,"mmmm") -> August | H23: =TEXT(E23, "dddd") -> Monday | I23: 0.61009259 | J23: =HOUR(I23) -> 14 | K23: =MINUTE(I23) -> 38 | L23: Laptop | M23: Computers | N23: 10 | O23: 822.19 | P23: =VLOOKUP(L23,'Product-cost'!A:B,2,FALSE) -> 600 | Q23: South America | R23: carlosrodriguez@techgadgetsco.com | S23: Packaging was damaged | T23: Negative | U23: =O23*N23 -> 8221.9 | V23: =P23*N23 -> 6000 | W23: =VLOOKUP(Q23,Taxrate!A:B,2,FALSE) -> 0.15 | X23: =U23*W23 -> 1233.285 | Y23: =VLOOKUP(L23,'Discount Rate'!A:B,2,FALSE) -> 0.05 | Z23: =Y23*U23 -> 411.095 | AA23: =U23-X23-Z23 -> 6577.52 | AB23: =AA23-V23 -> 577.52
A24: ORD-00023 | B24: CUST-438 | C24: REP-35 | D24: Carlos Rodriguez | E24: 46285 | F24: =YEAR(E24) -> 2026 | G24: =TEXT(E24,"mmmm") -> September | H24: =TEXT(E24, "dddd") -> Sunday | I24: 0.83146991 | J24: =HOUR(I24) -> 19 | K24: =MINUTE(I24) -> 57 | L24: Smartwatch | M24: Wearables | N24: 7 | O24: 252.69 | P24: =VLOOKUP(L24,'Product-cost'!A:B,2,FALSE) -> 150 | Q24: Africa | R24: carlosrodriguez@techgadgetsco.com | S24: Fantastic customer service | T24: Postive | U24: =O24*N24 -> 1768.83 | V24: =P24*N24 -> 1050 | W24: =VLOOKUP(Q24,Taxrate!A:B,2,FALSE) -> 0.12 | X24: =U24*W24 -> 212.2596 | Y24: =VLOOKUP(L24,'Discount Rate'!A:B,2,FALSE) -> 0.07 | Z24: =Y24*U24 -> 123.8181 | AA24: =U24-X24-Z24 -> 1432.7523 | AB24: =AA24-V24 -> 382.7523
A25: ORD-00024 | B25: CUST-100 | C25: REP-20 | D25: Sophie Lee | E25: 45446 | F25: =YEAR(E25) -> 2024 | G25: =TEXT(E25,"mmmm") -> June | H25: =TEXT(E25, "dddd") -> Monday | I25: 0.85946759 | J25: =HOUR(I25) -> 20 | K25: =MINUTE(I25) -> 37 | L25: Tablet | M25: Tablets | N25: 8 | O25: 422.23 | P25: =VLOOKUP(L25,'Product-cost'!A:B,2,FALSE) -> 200 | Q25: Europe | R25: sophielee@sales.techg.com | T25: Neutral | U25: =O25*N25 -> 3377.84 | V25: =P25*N25 -> 1600 | W25: =VLOOKUP(Q25,Taxrate!A:B,2,FALSE) -> 0.2 | X25: =U25*W25 -> 675.568 | Y25: =VLOOKUP(L25,'Discount Rate'!A:B,2,FALSE) -> 0.08 | Z25: =Y25*U25 -> 270.2272 | AA25: =U25-X25-Z25 -> 2432.0448 | AB25: =AA25-V25 -> 832.0448
A26: ORD-00025 | B26: CUST-417 | C26: REP-17 | D26: Maria Garcia | E26: 45228 | F26: =YEAR(E26) -> 2023 | G26: =TEXT(E26,"mmmm") -> October | H26: =TEXT(E26, "dddd") -> Sunday | I26: 0.34409722 | J26: =HOUR(I26) -> 8 | K26: =MINUTE(I26) -> 15 | L26: Smartwatch | M26: Wearables | N26: 2 | O26: 273.48 | P26: =VLOOKUP(L26,'Product-cost'!A:B,2,FALSE) -> 150 | Q26: Africa | R26: mariagarcia@techgadgetsco.com | T26: Neutral | U26: =O26*N26 -> 546.96 | V26: =P26*N26 -> 300 | W26: =VLOOKUP(Q26,Taxrate!A:B,2,FALSE) -> 0.12 | X26: =U26*W26 -> 65.6352 | Y26: =VLOOKUP(L26,'Discount Rate'!A:B,2,FALSE) -> 0.07 | Z26: =Y26*U26 -> 38.2872 | AA26: =U26-X26-Z26 -> 443.0376 | AB26: =AA26-V26 -> 143.0376
A27: ORD-00026 | B27: CUST-981 | C27: REP-13 | D27: Ahmed Khan | E27: 45375 | F27: =YEAR(E27) -> 2024 | G27: =TEXT(E27,"mmmm") -> March | H27: =TEXT(E27, "dddd") -> Sunday | I27: 0.86427083 | J27: =HOUR(I27) -> 20 | K27: =MINUTE(I27) -> 44 | L27: Headphones | M27: Audio | N27: 7 | O27: 183.63 | P27: =VLOOKUP(L27,'Product-cost'!A:B,2,FALSE) -> 50 | Q27: South America | R27: ahmedkhan@sales.techg.com | S27: Great product | T27: Postive | U27: =O27*N27 -> 1285.41 | V27: =P27*N27 -> 350 | W27: =VLOOKUP(Q27,Taxrate!A:B,2,FALSE) -> 0.15 | X27: =U27*W27 -> 192.8115 | Y27: =VLOOKUP(L27,'Discount Rate'!A:B,2,FALSE) -> 0.03 | Z27: =Y27*U27 -> 38.5623 | AA27: =U27-X27-Z27 -> 1054.0362 | AB27: =AA27-V27 -> 704.0362
A28: ORD-00027 | B28: CUST-836 | C28: REP-32 | D28: Maria Garcia | E28: 46049 | F28: =YEAR(E28) -> 2026 | G28: =TEXT(E28,"mmmm") -> January | H28: =TEXT(E28, "dddd") -> Tuesday | I28: 0.44994213 | J28: =HOUR(I28) -> 10 | K28: =MINUTE(I28) -> 47 | L28: Headphones | M28: Audio | N28: 13 | O28: 167.82 | P28: =VLOOKUP(L28,'Product-cost'!A:B,2,FALSE) -> 50 | Q28: Africa | R28: mariagarcia@techgadgetsco.com | T28: Neutral | U28: =O28*N28 -> 2181.66 | V28: =P28*N28 -> 650 | W28: =VLOOKUP(Q28,Taxrate!A:B,2,FALSE) -> 0.12 | X28: =U28*W28 -> 261.7992 | Y28: =VLOOKUP(L28,'Discount Rate'!A:B,2,FALSE) -> 0.03 | Z28: =Y28*U28 -> 65.4498 | AA28: =U28-X28-Z28 -> 1854.411 | AB28: =AA28-V28 -> 1204.411
A29: ORD-00028 | B29: CUST-182 | C29: REP-14 | D29: Maria Garcia | E29: 45400 | F29: =YEAR(E29) -> 2024 | G29: =TEXT(E29,"mmmm") -> April | H29: =TEXT(E29, "dddd") -> Thursday | I29: 0.7984375 | J29: =HOUR(I29) -> 19 | K29: =MINUTE(I29) -> 9 | L29: Smartphone | M29: Mobile Devices | N29: 7 | O29: 642.78 | P29: =VLOOKUP(L29,'Product-cost'!A:B,2,FALSE) -> 300 | Q29: South America | R29: mariagarcia@techgadgetsco.com | S29: Excellent quality | T29: Postive | U29: =O29*N29 -> 4499.46 | V29: =P29*N29 -> 2100 | W29: =VLOOKUP(Q29,Taxrate!A:B,2,FALSE) -> 0.15 | X29: =U29*W29 -> 674.919 | Y29: =VLOOKUP(L29,'Discount Rate'!A:B,2,FALSE) -> 0.1 | Z29: =Y29*U29 -> 449.946 | AA29: =U29-X29-Z29 -> 3374.595 | AB29: =AA29-V29 -> 1274.595
A30: ORD-00029 | B30: CUST-106 | C30: REP-22 | D30: Fatima Adebayo | E30: 45903 | F30: =YEAR(E30) -> 2025 | G30: =TEXT(E30,"mmmm") -> September | H30: =TEXT(E30, "dddd") -> Wednesday | I30: 0.69984954 | J30: =HOUR(I30) -> 16 | K30: =MINUTE(I30) -> 47 | L30: Smartwatch | M30: Wearables | N30: 15 | O30: 200.14 | P30: =VLOOKUP(L30,'Product-cost'!A:B,2,FALSE) -> 150 | Q30: South America | R30: fatimaadebayo@sales.techg.com | S30: Highly recommend | T30: Postive | U30: =O30*N30 -> 3002.1 | V30: =P30*N30 -> 2250 | W30: =VLOOKUP(Q30,Taxrate!A:B,2,FALSE) -> 0.15 | X30: =U30*W30 -> 450.315 | Y30: =VLOOKUP(L30,'Discount Rate'!A:B,2,FALSE) -> 0.07 | Z30: =Y30*U30 -> 210.147 | AA30: =U30-X30-Z30 -> 2341.638 | AB30: =AA30-V30 -> 91.638
A31: ORD-00030 | B31: CUST-737 | C31: REP-33 | D31: Ahmed Khan | E31: 45733 | F31: =YEAR(E31) -> 2025 | G31: =TEXT(E31,"mmmm") -> March | H31: =TEXT(E31, "dddd") -> Monday | I31: 0.40378472 | J31: =HOUR(I31) -> 9 | K31: =MINUTE(I31) -> 41 | L31: Smartphone | M31: Mobile Devices | N31: 3 | O31: 500 | P31: =VLOOKUP(L31,'Product-cost'!A:B,2,FALSE) -> 300 | Q31: South America | R31: ahmedkhan@sales.techg.com | S31: Highly recommend | T31: Postive | U31: =O31*N31 -> 1500 | V31: =P31*N31 -> 900 | W31: =VLOOKUP(Q31,Taxrate!A:B,2,FALSE) -> 0.15 | X31: =U31*W31 -> 225 | Y31: =VLOOKUP(L31,'Discount Rate'!A:B,2,FALSE) -> 0.1 | Z31: =Y31*U31 -> 150 | AA31: =U31-X31-Z31 -> 1125 | AB31: =AA31-V31 -> 225
A32: ORD-00031 | B32: CUST-954 | C32: REP-12 | D32: Olivia Patel | E32: 45171 | F32: =YEAR(E32) -> 2023 | G32: =TEXT(E32,"mmmm") -> September | H32: =TEXT(E32, "dddd") -> Saturday | I32: 0.55186343 | J32: =HOUR(I32) -> 13 | K32: =MINUTE(I32) -> 14 | L32: Laptop | M32: Computers | N32: 11 | O32: 500 | P32: =VLOOKUP(L32,'Product-cost'!A:B,2,FALSE) -> 600 | Q32: North America | R32: oliviapatel@tg.inc | S32: A bit expensive but worth it | T32: Neutral | U32: =O32*N32 -> 5500 | V32: =P32*N32 -> 6600 | W32: =VLOOKUP(Q32,Taxrate!A:B,2,FALSE) -> 0.07 | X32: =U32*W32 -> 385 | Y32: =VLOOKUP(L32,'Discount Rate'!A:B,2,FALSE) -> 0.05 | Z32: =Y32*U32 -> 275 | AA32: =U32-X32-Z32 -> 4840 | AB32: =AA32-V32 -> -1760
A33: ORD-00032 | B33: CUST-323 | C33: REP-28 | D33: Maria Garcia | E33: 45682 | F33: =YEAR(E33) -> 2025 | G33: =TEXT(E33,"mmmm") -> January | H33: =TEXT(E33, "dddd") -> Saturday | I33: 0.7352662 | J33: =HOUR(I33) -> 17 | K33: =MINUTE(I33) -> 38 | L33: Laptop | M33: Computers | N33: 3 | O33: 854.05 | P33: =VLOOKUP(L33,'Product-cost'!A:B,2,FALSE) -> 600 | Q33: North America | R33: mariagarcia@tg.inc | S33: Highly recommend | T33: Postive | U33: =O33*N33 -> 2562.15 | V33: =P33*N33 -> 1800 | W33: =VLOOKUP(Q33,Taxrate!A:B,2,FALSE) -> 0.07 | X33: =U33*W33 -> 179.3505 | Y33: =VLOOKUP(L33,'Discount Rate'!A:B,2,FALSE) -> 0.05 | Z33: =Y33*U33 -> 128.1075 | AA33: =U33-X33-Z33 -> 2254.692 | AB33: =AA33-V33 -> 454.692
A34: ORD-00033 | B34: CUST-807 | C34: REP-17 | D34: Maria Garcia | E34: 46354 | F34: =YEAR(E34) -> 2026 | G34: =TEXT(E34,"mmmm") -> November | H34: =TEXT(E34, "dddd") -> Saturday | I34: 0.90530093 | J34: =HOUR(I34) -> 21 | K34: =MINUTE(I34) -> 43 | L34: Laptop | M34: Computers | N34: 10 | O34: 973.6 | P34: =VLOOKUP(L34,'Product-cost'!A:B,2,FALSE) -> 600 | Q34: South America | R34: mariagarcia@techgadgetsco.com | S34: Excellent quality | T34: Postive | U34: =O34*N34 -> 9736 | V34: =P34*N34 -> 6000 | W34: =VLOOKUP(Q34,Taxrate!A:B,2,FALSE) -> 0.15 | X34: =U34*W34 -> 1460.4 | Y34: =VLOOKUP(L34,'Discount Rate'!A:B,2,FALSE) -> 0.05 | Z34: =Y34*U34 -> 486.8 | AA34: =U34-X34-Z34 -> 7788.8 | AB34: =AA34-V34 -> 1788.8
A35: ORD-00034 | B35: CUST-470 | C35: REP-28 | D35: Maria Garcia | E35: 45936 | F35: =YEAR(E35) -> 2025 | G35: =TEXT(E35,"mmmm") -> October | H35: =TEXT(E35, "dddd") -> Monday | I35: 0.81505787 | J35: =HOUR(I35) -> 19 | K35: =MINUTE(I35) -> 33 | L35: Tablet | M35: Tablets | N35: 15 | O35: 416.7 | P35: =VLOOKUP(L35,'Product-cost'!A:B,2,FALSE) -> 200 | Q35: South America | R35: mariagarcia@sales.techg.com | S35: Very satisfied | T35: Postive | U35: =O35*N35 -> 6250.5 | V35: =P35*N35 -> 3000 | W35: =VLOOKUP(Q35,Taxrate!A:B,2,FALSE) -> 0.15 | X35: =U35*W35 -> 937.575 | Y35: =VLOOKUP(L35,'Discount Rate'!A:B,2,FALSE) -> 0.08 | Z35: =Y35*U35 -> 500.04 | AA35: =U35-X35-Z35 -> 4812.885 | AB35: =AA35-V35 -> 1812.885
A36: ORD-00035 | B36: CUST-349 | C36: REP-28 | D36: Maria Garcia | E36: 45615 | F36: =YEAR(E36) -> 2024 | G36: =TEXT(E36,"mmmm") -> November | H36: =TEXT(E36, "dddd") -> Tuesday | I36: 0.66273148 | J36: =HOUR(I36) -> 15 | K36: =MINUTE(I36) -> 54 | L36: Smartphone | M36: Mobile Devices | N36: 6 | O36: 582.1 | P36: =VLOOKUP(L36,'Product-cost'!A:B,2,FALSE) -> 300 | Q36: Africa | R36: mariagarcia@tg.inc | T36: Neutral | U36: =O36*N36 -> 3492.6 | V36: =P36*N36 -> 1800 | W36: =VLOOKUP(Q36,Taxrate!A:B,2,FALSE) -> 0.12 | X36: =U36*W36 -> 419.112 | Y36: =VLOOKUP(L36,'Discount Rate'!A:B,2,FALSE) -> 0.1 | Z36: =Y36*U36 -> 349.26 | AA36: =U36-X36-Z36 -> 2724.228 | AB36: =AA36-V36 -> 924.228
A37: ORD-00036 | B37: CUST-876 | C37: REP-17 | D37: Maria Garcia | E37: 46249 | F37: =YEAR(E37) -> 2026 | G37: =TEXT(E37,"mmmm") -> August | H37: =TEXT(E37, "dddd") -> Saturday | I37: 0.6597338 | J37: =HOUR(I37) -> 15 | K37: =MINUTE(I37) -> 50 | L37: Laptop | M37: Computers | N37: 7 | O37: 953.1 | P37: =VLOOKUP(L37,'Product-cost'!A:B,2,FALSE) -> 600 | Q37: Africa | R37: mariagarcia@tg.inc | S37: Great product | T37: Postive | U37: =O37*N37 -> 6671.7 | V37: =P37*N37 -> 4200 | W37: =VLOOKUP(Q37,Taxrate!A:B,2,FALSE) -> 0.12 | X37: =U37*W37 -> 800.604 | Y37: =VLOOKUP(L37,'Discount Rate'!A:B,2,FALSE) -> 0.05 | Z37: =Y37*U37 -> 333.585 | AA37: =U37-X37-Z37 -> 5537.511 | AB37: =AA37-V37 -> 1337.511
A38: ORD-00037 | B38: CUST-336 | C38: REP-13 | D38: Ahmed Khan | E38: 45514 | F38: =YEAR(E38) -> 2024 | G38: =TEXT(E38,"mmmm") -> August | H38: =TEXT(E38, "dddd") -> Saturday | I38: 0.81583333 | J38: =HOUR(I38) -> 19 | K38: =MINUTE(I38) -> 34 | L38: Smartphone | M38: Mobile Devices | N38: 12 | O38: 697.38 | P38: =VLOOKUP(L38,'Product-cost'!A:B,2,FALSE) -> 300 | Q38: Africa | R38: ahmedkhan@tg.inc | T38: Neutral | U38: =O38*N38 -> 8368.56 | V38: =P38*N38 -> 3600 | W38: =VLOOKUP(Q38,Taxrate!A:B,2,FALSE) -> 0.12 | X38: =U38*W38 -> 1004.2272 | Y38: =VLOOKUP(L38,'Discount Rate'!A:B,2,FALSE) -> 0.1 | Z38: =Y38*U38 -> 836.856 | AA38: =U38-X38-Z38 -> 6527.4768 | AB38: =AA38-V38 -> 2927.4768
A39: ORD-00038 | B39: CUST-646 | C39: REP-14 | D39: Maria Garcia | E39: 45020 | F39: =YEAR(E39) -> 2023 | G39: =TEXT(E39,"mmmm") -> April | H39: =TEXT(E39, "dddd") -> Tuesday | I39: 0.67967593 | J39: =HOUR(I39) -> 16 | K39: =MINUTE(I39) -> 18 | L39: Smartphone | M39: Mobile Devices | N39: 13 | O39: 741.82 | P39: =VLOOKUP(L39,'Product-cost'!A:B,2,FALSE) -> 300 | Q39: Africa | R39: mariagarcia@sales.techg.com | S39: Quick shipping | T39: Postive | U39: =O39*N39 -> 9643.66 | V39: =P39*N39 -> 3900 | W39: =VLOOKUP(Q39,Taxrate!A:B,2,FALSE) -> 0.12 | X39: =U39*W39 -> 1157.2392 | Y39: =VLOOKUP(L39,'Discount Rate'!A:B,2,FALSE) -> 0.1 | Z39: =Y39*U39 -> 964.366 | AA39: =U39-X39-Z39 -> 7522.0548 | AB39: =AA39-V39 -> 3622.0548
A40: ORD-00039 | B40: CUST-166 | C40: REP-23 | D40: Noah Kim | E40: 44932 | F40: =YEAR(E40) -> 2023 | G40: =TEXT(E40,"mmmm") -> January | H40: =TEXT(E40, "dddd") -> Friday | I40: 0.42350694 | J40: =HOUR(I40) -> 10 | K40: =MINUTE(I40) -> 9 | L40: Smartwatch | M40: Wearables | N40: 2 | O40: 189.03 | P40: =VLOOKUP(L40,'Product-cost'!A:B,2,FALSE) -> 150 | Q40: South America | R40: noahkim@sales.techg.com | S40: Love the design | T40: Postive | U40: =O40*N40 -> 378.06 | V40: =P40*N40 -> 300 | W40: =VLOOKUP(Q40,Taxrate!A:B,2,FALSE) -> 0.15 | X40: =U40*W40 -> 56.709 | Y40: =VLOOKUP(L40,'Discount Rate'!A:B,2,FALSE) -> 0.07 | Z40: =Y40*U40 -> 26.4642 | AA40: =U40-X40-Z40 -> 294.8868 | AB40: =AA40-V40 -> -5.1132
...

Sheet dashboard
D1: SALES TECH DASHBORAD
B2: SALES TOLTAL REVENU | C2: TOTAL COST | D2: TOTAL TAX | E2: NUM OF ORDERS | F2: NUMOF SALES REP
B3: 1331871.6 | C3: 867350 | D3: 215288.03 | E3: 435 | F3: 9

Sheet Product-cost
A1: Product | B1: Cost
A2: Laptop | B2: 600
A3: Smartphone | B3: 300
A4: Tablet | B4: 200
A5: Headphones | B5: 50
A6: Smartwatch | B6: 150

Sheet Taxrate
A1: Region | B1: TaxRate
A2: North America | B2: 0.07
A3: Europe | B3: 0.2
A4: Asia | B4: 0.1
A5: South America | B5: 0.15
A6: Africa | B6: 0.12

Sheet Discount Rate
A1: Product | B1: DiscountRate
A2: Laptop | B2: 0.05
A3: Smartphone | B3: 0.1
A4: Tablet | B4: 0.08
A5: Headphones | B5: 0.03
A6: Smartwatch | B6: 0.07
