Workbook

Sheet Sales Dataset
A1: OrderID | B1: CustomerID | C1: SalesRepID | D1: sales repname | E1: sales rep firstnname | F1: sales rep surname | G1: Date | H1: year | I1: month | J1: day | K1: Time | L1: hour | M1: minute | N1: seconds | O1: product | P1: product category | Q1: OrderQuantity | R1: UnitPrice | S1: Unit Cost | T1: sales region | U1: SalesRepEmail | V1: feeback | W1: feedback cateory | X1: Gross Revenue | Y1: Total Cost | Z1: Tax Rate | AA1: Tax Amount | AB1: Discount Rate | AC1: discount amount | AD1: Net Sales
A2: ORD-00001 | B2: CUST-754 | C2: REP-13 | D2: Ahmed Khan | E2: Ahmed | F2: Khan | G2: 45490 | H2: =YEAR(G2) -> 2024 | I2: =TEXT(G2,"mmmm") -> July | J2: =TEXT(G2,"dddd") -> Wednesday | K2: 0.46443287 | L2: =HOUR(K2) -> 11 | M2: =MINUTE(K2) -> 8 | N2: =SECOND(K2) -> 47 | O2: Laptop | P2: Computers | Q2: 15 | R2: 1095.25 | S2: =VLOOKUP(O2,'Product-cost'!A:B,2,) -> 600 | T2: North America | U2: ahmedkhan@tg.inc | V2: Excellent Quality | W2: positive | X2: =R2*Q2 -> 16428.75 | Y2: =S2*Q2 -> 9000 | Z2: =VLOOKUP(T2,Taxrate!A:B,2,FALSE) -> 0.07 | AA2: =X2*Z2 -> 1150.0125 | AB2: =VLOOKUP('Sales Dataset'!O2,'Discount Rate'!A:B,2,) -> 0.05 | AC2: =Y2*AB2 -> 450 | AD2: =Y2-AB2-Z2 -> 8999.88
A3: ORD-00002 | B3: CUST-529 | C3: REP-17 | D3: Maria Garcia | E3: Maria | F3: Garcia | G3: 46133 | H3: =YEAR(G3) -> 2026 | I3: =TEXT(G3,"mmmm") -> April | J3: =TEXT(G3,"dddd") -> Tuesday | K3: 0.87152778 | L3: =HOUR(K3) -> 20 | M3: =MINUTE(K3) -> 55 | N3: =SECOND(K3) -> 0 | O3: Smartphone | P3: Mobile Devices | Q3: 6 | R3: 544.59 | S3: =VLOOKUP(O3,'Product-cost'!A:B,2,) -> 300 | T3: Asia | U3: mariagarcia@tg.inc | V3: Fast Delivery | W3: positive | X3: =R3*Q3 -> 3267.54 | Y3: =S3*Q3 -> 1800 | Z3: =VLOOKUP(T3,Taxrate!A:B,2,FALSE) -> 0.1 | AA3: =X3*Z3 -> 326.754 | AB3: =VLOOKUP('Sales Dataset'!O3,'Discount Rate'!A:B,2,) -> 0.1 | AC3: =Y3*AB3 -> 180 | AD3: =Y3-AB3-Z3 -> 1799.8
A4: ORD-00003 | B4: CUST-649 | C4: REP-13 | D4: Ahmed Khan | E4: Ahmed | F4: Khan | G4: 45236 | H4: =YEAR(G4) -> 2023 | I4: =TEXT(G4,"mmmm") -> November | J4: =TEXT(G4,"dddd") -> Monday | K4: 0.90322917 | L4: =HOUR(K4) -> 21 | M4: =MINUTE(K4) -> 40 | N4: =SECOND(K4) -> 39 | O4: Tablet | P4: Tablets | Q4: 12 | R4: 500 | S4: =VLOOKUP(O4,'Product-cost'!A:B,2,) -> 200 | T4: Europe | U4: ahmedkhan@sales.techg.com | V4: Good Value For Money | W4: positive | X4: =R4*Q4 -> 6000 | Y4: =S4*Q4 -> 2400 | Z4: =VLOOKUP(T4,Taxrate!A:B,2,FALSE) -> 0.2 | AA4: =X4*Z4 -> 1200 | AB4: =VLOOKUP('Sales Dataset'!O4,'Discount Rate'!A:B,2,) -> 0.08 | AC4: =Y4*AB4 -> 192 | AD4: =Y4-AB4-Z4 -> 2399.72
A5: ORD-00004 | B5: CUST-266 | C5: REP-22 | D5: Fatima Adebayo | E5: Fatima | F5: Adebayo | G5: 45415 | H5: =YEAR(G5) -> 2024 | I5: =TEXT(G5,"mmmm") -> May | J5: =TEXT(G5,"dddd") -> Friday | K5: 0.83313657 | L5: =HOUR(K5) -> 19 | M5: =MINUTE(K5) -> 59 | N5: =SECOND(K5) -> 43 | O5: Laptop | P5: Computers | Q5: 3 | R5: 922.41 | S5: =VLOOKUP(O5,'Product-cost'!A:B,2,) -> 600 | T5: South America | U5: fatimaadebayo@sales.techg.com | V5: Very Satisfied | W5: positive | X5: =R5*Q5 -> 2767.23 | Y5: =S5*Q5 -> 1800 | Z5: =VLOOKUP(T5,Taxrate!A:B,2,FALSE) -> 0.15 | AA5: =X5*Z5 -> 415.0845 | AB5: =VLOOKUP('Sales Dataset'!O5,'Discount Rate'!A:B,2,) -> 0.05 | AC5: =Y5*AB5 -> 90 | AD5: =Y5-AB5-Z5 -> 1799.8
A6: ORD-00005 | B6: CUST-334 | C6: REP-11 | D6: Emma Dubois | E6: Emma | F6: Dubois | G6: 45661 | H6: =YEAR(G6) -> 2025 | I6: =TEXT(G6,"mmmm") -> January | J6: =TEXT(G6,"dddd") -> Saturday | K6: 0.38469907 | L6: =HOUR(K6) -> 9 | M6: =MINUTE(K6) -> 13 | N6: =SECOND(K6) -> 58 | O6: Smartwatch | P6: Wearables | Q6: 6 | R6: 230.92 | S6: =VLOOKUP(O6,'Product-cost'!A:B,2,) -> 150 | T6: South America | U6: emmadubois@techgadgetsco.com | W6: neutral | X6: =R6*Q6 -> 1385.52 | Y6: =S6*Q6 -> 900 | Z6: =VLOOKUP(T6,Taxrate!A:B,2,FALSE) -> 0.15 | AA6: =X6*Z6 -> 207.828 | AB6: =VLOOKUP('Sales Dataset'!O6,'Discount Rate'!A:B,2,) -> 0.07 | AC6: =Y6*AB6 -> 63 | AD6: =Y6-AB6-Z6 -> 899.78
A7: ORD-00006 | B7: CUST-470 | C7: REP-17 | D7: Maria Garcia | E7: Maria | F7: Garcia | G7: 45911 | H7: =YEAR(G7) -> 2025 | I7: =TEXT(G7,"mmmm") -> September | J7: =TEXT(G7,"dddd") -> Thursday | K7: 0.40836806 | L7: =HOUR(K7) -> 9 | M7: =MINUTE(K7) -> 48 | N7: =SECOND(K7) -> 3 | O7: Laptop | P7: Computers | Q7: 3 | R7: 1011.08 | S7: =VLOOKUP(O7,'Product-cost'!A:B,2,) -> 600 | T7: North America | U7: mariagarcia@techgadgetsco.com | W7: neutral | X7: =R7*Q7 -> 3033.24 | Y7: =S7*Q7 -> 1800 | Z7: =VLOOKUP(T7,Taxrate!A:B,2,FALSE) -> 0.07 | AA7: =X7*Z7 -> 212.3268 | AB7: =VLOOKUP('Sales Dataset'!O7,'Discount Rate'!A:B,2,) -> 0.05 | AC7: =Y7*AB7 -> 90 | AD7: =Y7-AB7-Z7 -> 1799.88
A8: ORD-00007 | B8: CUST-838 | C8: REP-13 | D8: Ahmed Khan | E8: Ahmed | F8: Khan | G8: 46150 | H8: =YEAR(G8) -> 2026 | I8: =TEXT(G8,"mmmm") -> May | J8: =TEXT(G8,"dddd") -> Friday | K8: 0.3878125 | L8: =HOUR(K8) -> 9 | M8: =MINUTE(K8) -> 18 | N8: =SECOND(K8) -> 27 | O8: Smartphone | P8: Mobile Devices | Q8: 12 | R8: 559.02 | S8: =VLOOKUP(O8,'Product-cost'!A:B,2,) -> 300 | T8: Africa | U8: ahmedkhan@sales.techg.com | W8: neutral | X8: =R8*Q8 -> 6708.24 | Y8: =S8*Q8 -> 3600 | Z8: =VLOOKUP(T8,Taxrate!A:B,2,FALSE) -> 0.12 | AA8: =X8*Z8 -> 804.9888 | AB8: =VLOOKUP('Sales Dataset'!O8,'Discount Rate'!A:B,2,) -> 0.1 | AC8: =Y8*AB8 -> 360 | AD8: =Y8-AB8-Z8 -> 3599.78
A9: ORD-00008 | B9: CUST-482 | C9: REP-15 | D9: Sophie Lee | E9: Sophie | F9: Lee | G9: 46013 | H9: =YEAR(G9) -> 2025 | I9: =TEXT(G9,"mmmm") -> December | J9: =TEXT(G9,"dddd") -> Monday | K9: 0.72258102 | L9: =HOUR(K9) -> 17 | M9: =MINUTE(K9) -> 20 | N9: =SECOND(K9) -> 31 | O9: Laptop | P9: Computers | Q9: 6 | R9: 1215.83 | S9: =VLOOKUP(O9,'Product-cost'!A:B,2,) -> 600 | T9: Asia | U9: sophielee@sales.techg.com | W9: neutral | X9: =R9*Q9 -> 7294.98 | Y9: =S9*Q9 -> 3600 | Z9: =VLOOKUP(T9,Taxrate!A:B,2,FALSE) -> 0.1 | AA9: =X9*Z9 -> 729.498 | AB9: =VLOOKUP('Sales Dataset'!O9,'Discount Rate'!A:B,2,) -> 0.05 | AC9: =Y9*AB9 -> 180 | AD9: =Y9-AB9-Z9 -> 3599.85
A10: ORD-00009 | B10: CUST-878 | C10: REP-33 | D10: Ahmed Khan | E10: Ahmed | F10: Khan | G10: 45189 | H10: =YEAR(G10) -> 2023 | I10: =TEXT(G10,"mmmm") -> September | J10: =TEXT(G10,"dddd") -> Wednesday | K10: 0.6737963 | L10: =HOUR(K10) -> 16 | M10: =MINUTE(K10) -> 10 | N10: =SECOND(K10) -> 16 | O10: Smartwatch | P10: Wearables | Q10: 7 | R10: 278.18 | S10: =VLOOKUP(O10,'Product-cost'!A:B,2,) -> 150 | T10: Europe | U10: ahmedkhan@sales.techg.com | V10: Fast Delivery | W10: positive | X10: =R10*Q10 -> 1947.26 | Y10: =S10*Q10 -> 1050 | Z10: =VLOOKUP(T10,Taxrate!A:B,2,FALSE) -> 0.2 | AA10: =X10*Z10 -> 389.452 | AB10: =VLOOKUP('Sales Dataset'!O10,'Discount Rate'!A:B,2,) -> 0.07 | AC10: =Y10*AB10 -> 73.5 | AD10: =Y10-AB10-Z10 -> 1049.73
A11: ORD-00010 | B11: CUST-330 | C11: REP-12 | D11: Olivia Patel | E11: Olivia | F11: Patel | G11: 44970 | H11: =YEAR(G11) -> 2023 | I11: =TEXT(G11,"mmmm") -> February | J11: =TEXT(G11,"dddd") -> Monday | K11: 0.71805556 | L11: =HOUR(K11) -> 17 | M11: =MINUTE(K11) -> 14 | N11: =SECOND(K11) -> 0 | O11: Laptop | P11: Computers | Q11: 1 | R11: 1252.71 | S11: =VLOOKUP(O11,'Product-cost'!A:B,2,) -> 600 | T11: Asia | U11: oliviapatel@tg.inc | V11: Packaging Was Damaged | W11: negative | X11: =R11*Q11 -> 1252.71 | Y11: =S11*Q11 -> 600 | Z11: =VLOOKUP(T11,Taxrate!A:B,2,FALSE) -> 0.1 | AA11: =X11*Z11 -> 125.271 | AB11: =VLOOKUP('Sales Dataset'!O11,'Discount Rate'!A:B,2,) -> 0.05 | AC11: =Y11*AB11 -> 30 | AD11: =Y11-AB11-Z11 -> 599.85
A12: ORD-00011 | B12: CUST-690 | C12: REP-29 | D12: Sophie Lee | E12: Sophie | F12: Lee | G12: 45895 | H12: =YEAR(G12) -> 2025 | I12: =TEXT(G12,"mmmm") -> August | J12: =TEXT(G12,"dddd") -> Tuesday | K12: 0.46256944 | L12: =HOUR(K12) -> 11 | M12: =MINUTE(K12) -> 6 | N12: =SECOND(K12) -> 6 | O12: Headphones | P12: Audio | Q12: 7 | R12: 174.68 | S12: =VLOOKUP(O12,'Product-cost'!A:B,2,) -> 50 | T12: North America | U12: sophielee@tg.inc | V12: Good Value For Money | W12: positive | X12: =R12*Q12 -> 1222.76 | Y12: =S12*Q12 -> 350 | Z12: =VLOOKUP(T12,Taxrate!A:B,2,FALSE) -> 0.07 | AA12: =X12*Z12 -> 85.5932 | AB12: =VLOOKUP('Sales Dataset'!O12,'Discount Rate'!A:B,2,) -> 0.03 | AC12: =Y12*AB12 -> 10.5 | AD12: =Y12-AB12-Z12 -> 349.9
A13: ORD-00012 | B13: CUST-532 | C13: REP-15 | D13: Sophie Lee | E13: Sophie | F13: Lee | G13: 45785 | H13: =YEAR(G13) -> 2025 | I13: =TEXT(G13,"mmmm") -> May | J13: =TEXT(G13,"dddd") -> Thursday | K13: 0.91601852 | L13: =HOUR(K13) -> 21 | M13: =MINUTE(K13) -> 59 | N13: =SECOND(K13) -> 4 | O13: Headphones | P13: Audio | Q13: 14 | R13: 123.79 | S13: =VLOOKUP(O13,'Product-cost'!A:B,2,) -> 50 | T13: Africa | U13: sophielee@tg.inc | V13: Very Satisfied | W13: positive | X13: =R13*Q13 -> 1733.06 | Y13: =S13*Q13 -> 700 | Z13: =VLOOKUP(T13,Taxrate!A:B,2,FALSE) -> 0.12 | AA13: =X13*Z13 -> 207.9672 | AB13: =VLOOKUP('Sales Dataset'!O13,'Discount Rate'!A:B,2,) -> 0.03 | AC13: =Y13*AB13 -> 21 | AD13: =Y13-AB13-Z13 -> 699.85
A14: ORD-00013 | B14: CUST-510 | C14: REP-11 | D14: Emma Dubois | E14: Emma | F14: Dubois | G14: 45703 | H14: =YEAR(G14) -> 2025 | I14: =TEXT(G14,"mmmm") -> February | J14: =TEXT(G14,"dddd") -> Saturday | K14: 0.59512731 | L14: =HOUR(K14) -> 14 | M14: =MINUTE(K14) -> 16 | N14: =SECOND(K14) -> 59 | O14: Headphones | P14: Audio | Q14: 12 | R14: 194.66 | S14: =VLOOKUP(O14,'Product-cost'!A:B,2,) -> 50 | T14: Africa | U14: emmadubois@tg.inc | V14: Packaging Was Damaged | W14: negative | X14: =R14*Q14 -> 2335.92 | Y14: =S14*Q14 -> 600 | Z14: =VLOOKUP(T14,Taxrate!A:B,2,FALSE) -> 0.12 | AA14: =X14*Z14 -> 280.3104 | AB14: =VLOOKUP('Sales Dataset'!O14,'Discount Rate'!A:B,2,) -> 0.03 | AC14: =Y14*AB14 -> 18 | AD14: =Y14-AB14-Z14 -> 599.85
A15: ORD-00014 | B15: CUST-865 | C15: REP-21 | D15: Fatima Adebayo | E15: Fatima | F15: Adebayo | G15: 45029 | H15: =YEAR(G15) -> 2023 | I15: =TEXT(G15,"mmmm") -> April | J15: =TEXT(G15,"dddd") -> Thursday | K15: 0.70756944 | L15: =HOUR(K15) -> 16 | M15: =MINUTE(K15) -> 58 | N15: =SECOND(K15) -> 54 | O15: Smartwatch | P15: Wearables | Q15: 9 | R15: 500 | S15: =VLOOKUP(O15,'Product-cost'!A:B,2,) -> 150 | T15: Europe | U15: fatimaadebayo@tg.inc | W15: neutral | X15: =R15*Q15 -> 4500 | Y15: =S15*Q15 -> 1350 | Z15: =VLOOKUP(T15,Taxrate!A:B,2,FALSE) -> 0.2 | AA15: =X15*Z15 -> 900 | AB15: =VLOOKUP('Sales Dataset'!O15,'Discount Rate'!A:B,2,) -> 0.07 | AC15: =Y15*AB15 -> 94.5 | AD15: =Y15-AB15-Z15 -> 1349.73
A16: ORD-00015 | B16: CUST-708 | C16: REP-11 | D16: Emma Dubois | E16: Emma | F16: Dubois | G16: 45094 | H16: =YEAR(G16) -> 2023 | I16: =TEXT(G16,"mmmm") -> June | J16: =TEXT(G16,"dddd") -> Saturday | K16: 0.77611111 | L16: =HOUR(K16) -> 18 | M16: =MINUTE(K16) -> 37 | N16: =SECOND(K16) -> 36 | O16: Smartwatch | P16: Wearables | Q16: 5 | R16: 254.78 | S16: =VLOOKUP(O16,'Product-cost'!A:B,2,) -> 150 | T16: Europe | U16: emmadubois@sales.techg.com | V16: Perfect Fit | W16: positive | X16: =R16*Q16 -> 1273.9 | Y16: =S16*Q16 -> 750 | Z16: =VLOOKUP(T16,Taxrate!A:B,2,FALSE) -> 0.2 | AA16: =X16*Z16 -> 254.78 | AB16: =VLOOKUP('Sales Dataset'!O16,'Discount Rate'!A:B,2,) -> 0.07 | AC16: =Y16*AB16 -> 52.5 | AD16: =Y16-AB16-Z16 -> 749.73
A17: ORD-00016 | B17: CUST-569 | C17: REP-35 | D17: Carlos Rodriguez | E17: Carlos | F17: Rodriguez | G17: 45131 | H17: =YEAR(G17) -> 2023 | I17: =TEXT(G17,"mmmm") -> July | J17: =TEXT(G17,"dddd") -> Monday | K17: 0.67606481 | L17: =HOUR(K17) -> 16 | M17: =MINUTE(K17) -> 13 | N17: =SECOND(K17) -> 32 | O17: Tablet | P17: Tablets | Q17: 6 | R17: 495.85 | S17: =VLOOKUP(O17,'Product-cost'!A:B,2,) -> 200 | T17: Asia | U17: carlosrodriguez@tg.inc | W17: neutral | X17: =R17*Q17 -> 2975.1 | Y17: =S17*Q17 -> 1200 | Z17: =VLOOKUP(T17,Taxrate!A:B,2,FALSE) -> 0.1 | AA17: =X17*Z17 -> 297.51 | AB17: =VLOOKUP('Sales Dataset'!O17,'Discount Rate'!A:B,2,) -> 0.08 | AC17: =Y17*AB17 -> 96 | AD17: =Y17-AB17-Z17 -> 1199.82
A18: ORD-00017 | B18: CUST-108 | C18: REP-33 | D18: Ahmed Khan | E18: Ahmed | F18: Khan | G18: 46285 | H18: =YEAR(G18) -> 2026 | I18: =TEXT(G18,"mmmm") -> September | J18: =TEXT(G18,"dddd") -> Sunday | K18: 0.4278588 | L18: =HOUR(K18) -> 10 | M18: =MINUTE(K18) -> 16 | N18: =SECOND(K18) -> 7 | O18: Laptop | P18: Computers | Q18: 3 | R18: 1102.41 | S18: =VLOOKUP(O18,'Product-cost'!A:B,2,) -> 600 | T18: Asia | U18: ahmedkhan@tg.inc | V18: Battery Life Amazing | W18: positive | X18: =R18*Q18 -> 3307.23 | Y18: =S18*Q18 -> 1800 | Z18: =VLOOKUP(T18,Taxrate!A:B,2,FALSE) -> 0.1 | AA18: =X18*Z18 -> 330.723 | AB18: =VLOOKUP('Sales Dataset'!O18,'Discount Rate'!A:B,2,) -> 0.05 | AC18: =Y18*AB18 -> 90 | AD18: =Y18-AB18-Z18 -> 1799.85
A19: ORD-00018 | B19: CUST-749 | C19: REP-24 | D19: Liam Chen | E19: Liam | F19: Chen | G19: 44930 | H19: =YEAR(G19) -> 2023 | I19: =TEXT(G19,"mmmm") -> January | J19: =TEXT(G19,"dddd") -> Wednesday | K19: 0.57578704 | L19: =HOUR(K19) -> 13 | M19: =MINUTE(K19) -> 49 | N19: =SECOND(K19) -> 8 | O19: Tablet | P19: Tablets | Q19: 8 | R19: 405.54 | S19: =VLOOKUP(O19,'Product-cost'!A:B,2,) -> 200 | T19: North America | U19: liamchen@sales.techg.com | V19: A Bit Expensive But Worth It | W19: neutral | X19: =R19*Q19 -> 3244.32 | Y19: =S19*Q19 -> 1600 | Z19: =VLOOKUP(T19,Taxrate!A:B,2,FALSE) -> 0.07 | AA19: =X19*Z19 -> 227.1024 | AB19: =VLOOKUP('Sales Dataset'!O19,'Discount Rate'!A:B,2,) -> 0.08 | AC19: =Y19*AB19 -> 128 | AD19: =Y19-AB19-Z19 -> 1599.85
A20: ORD-00019 | B20: CUST-251 | C20: REP-24 | D20: Liam Chen | E20: Liam | F20: Chen | G20: 45012 | H20: =YEAR(G20) -> 2023 | I20: =TEXT(G20,"mmmm") -> March | J20: =TEXT(G20,"dddd") -> Monday | K20: 0.58193287 | L20: =HOUR(K20) -> 13 | M20: =MINUTE(K20) -> 57 | N20: =SECOND(K20) -> 59 | O20: Laptop | P20: Computers | Q20: 4 | R20: 1133.47 | S20: =VLOOKUP(O20,'Product-cost'!A:B,2,) -> 600 | T20: Asia | U20: liamchen@techgadgetsco.com | V20: A Bit Expensive But Worth It | W20: neutral | X20: =R20*Q20 -> 4533.88 | Y20: =S20*Q20 -> 2400 | Z20: =VLOOKUP(T20,Taxrate!A:B,2,FALSE) -> 0.1 | AA20: =X20*Z20 -> 453.388 | AB20: =VLOOKUP('Sales Dataset'!O20,'Discount Rate'!A:B,2,) -> 0.05 | AC20: =Y20*AB20 -> 120 | AD20: =Y20-AB20-Z20 -> 2399.85
A21: ORD-00020 | B21: CUST-919 | C21: REP-15 | D21: Sophie Lee | E21: Sophie | F21: Lee | G21: 44977 | H21: =YEAR(G21) -> 2023 | I21: =TEXT(G21,"mmmm") -> February | J21: =TEXT(G21,"dddd") -> Monday | K21: 0.83288194 | L21: =HOUR(K21) -> 19 | M21: =MINUTE(K21) -> 59 | N21: =SECOND(K21) -> 21 | O21: Headphones | P21: Audio | Q21: 14 | R21: 138.61 | S21: =VLOOKUP(O21,'Product-cost'!A:B,2,) -> 50 | T21: Europe | U21: sophielee@tg.inc | V21: Battery Life Amazing | W21: positive | X21: =R21*Q21 -> 1940.54 | Y21: =S21*Q21 -> 700 | Z21: =VLOOKUP(T21,Taxrate!A:B,2,FALSE) -> 0.2 | AA21: =X21*Z21 -> 388.108 | AB21: =VLOOKUP('Sales Dataset'!O21,'Discount Rate'!A:B,2,) -> 0.03 | AC21: =Y21*AB21 -> 21 | AD21: =Y21-AB21-Z21 -> 699.77
A22: ORD-00021 | B22: CUST-412 | C22: REP-17 | D22: Maria Garcia | E22: Maria | F22: Garcia | G22: 44975 | H22: =YEAR(G22) -> 2023 | I22: =TEXT(G22,"mmmm") -> February | J22: =TEXT(G22,"dddd") -> Saturday | K22: 0.59811343 | L22: =HOUR(K22) -> 14 | M22: =MINUTE(K22) -> 21 | N22: =SECOND(K22) -> 17 | O22: Laptop | P22: Computers | Q22: 5 | R22: 1054.7 | S22: =VLOOKUP(O22,'Product-cost'!A:B,2,) -> 600 | T22: Africa | U22: mariagarcia@techgadgetsco.com | W22: neutral | X22: =R22*Q22 -> 5273.5 | Y22: =S22*Q22 -> 3000 | Z22: =VLOOKUP(T22,Taxrate!A:B,2,FALSE) -> 0.12 | AA22: =X22*Z22 -> 632.82 | AB22: =VLOOKUP('Sales Dataset'!O22,'Discount Rate'!A:B,2,) -> 0.05 | AC22: =Y22*AB22 -> 150 | AD22: =Y22-AB22-Z22 -> 2999.83
A23: ORD-00022 | B23: CUST-211 | C23: REP-35 | D23: Carlos Rodriguez | E23: Carlos | F23: Rodriguez | G23: 45516 | H23: =YEAR(G23) -> 2024 | I23: =TEXT(G23,"mmmm") -> August | J23: =TEXT(G23,"dddd") -> Monday | K23: 0.61009259 | L23: =HOUR(K23) -> 14 | M23: =MINUTE(K23) -> 38 | N23: =SECOND(K23) -> 32 | O23: Laptop | P23: Computers | Q23: 10 | R23: 822.19 | S23: =VLOOKUP(O23,'Product-cost'!A:B,2,) -> 600 | T23: South America | U23: carlosrodriguez@techgadgetsco.com | V23: Packaging Was Damaged | W23: negative | X23: =R23*Q23 -> 8221.9 | Y23: =S23*Q23 -> 6000 | Z23: =VLOOKUP(T23,Taxrate!A:B,2,FALSE) -> 0.15 | AA23: =X23*Z23 -> 1233.285 | AB23: =VLOOKUP('Sales Dataset'!O23,'Discount Rate'!A:B,2,) -> 0.05 | AC23: =Y23*AB23 -> 300 | AD23: =Y23-AB23-Z23 -> 5999.8
A24: ORD-00023 | B24: CUST-438 | C24: REP-35 | D24: Carlos Rodriguez | E24: Carlos | F24: Rodriguez | G24: 46285 | H24: =YEAR(G24) -> 2026 | I24: =TEXT(G24,"mmmm") -> September | J24: =TEXT(G24,"dddd") -> Sunday | K24: 0.83146991 | L24: =HOUR(K24) -> 19 | M24: =MINUTE(K24) -> 57 | N24: =SECOND(K24) -> 19 | O24: Smartwatch | P24: Wearables | Q24: 7 | R24: 252.69 | S24: =VLOOKUP(O24,'Product-cost'!A:B,2,) -> 150 | T24: Africa | U24: carlosrodriguez@techgadgetsco.com | V24: Fantastic Customer Service | W24: positive | X24: =R24*Q24 -> 1768.83 | Y24: =S24*Q24 -> 1050 | Z24: =VLOOKUP(T24,Taxrate!A:B,2,FALSE) -> 0.12 | AA24: =X24*Z24 -> 212.2596 | AB24: =VLOOKUP('Sales Dataset'!O24,'Discount Rate'!A:B,2,) -> 0.07 | AC24: =Y24*AB24 -> 73.5 | AD24: =Y24-AB24-Z24 -> 1049.81
A25: ORD-00024 | B25: CUST-100 | C25: REP-20 | D25: Sophie Lee | E25: Sophie | F25: Lee | G25: 45446 | H25: =YEAR(G25) -> 2024 | I25: =TEXT(G25,"mmmm") -> June | J25: =TEXT(G25,"dddd") -> Monday | K25: 0.85946759 | L25: =HOUR(K25) -> 20 | M25: =MINUTE(K25) -> 37 | N25: =SECOND(K25) -> 38 | O25: Tablet | P25: Tablets | Q25: 8 | R25: 422.23 | S25: =VLOOKUP(O25,'Product-cost'!A:B,2,) -> 200 | T25: Europe | U25: sophielee@sales.techg.com | W25: neutral | X25: =R25*Q25 -> 3377.84 | Y25: =S25*Q25 -> 1600 | Z25: =VLOOKUP(T25,Taxrate!A:B,2,FALSE) -> 0.2 | AA25: =X25*Z25 -> 675.568 | AB25: =VLOOKUP('Sales Dataset'!O25,'Discount Rate'!A:B,2,) -> 0.08 | AC25: =Y25*AB25 -> 128 | AD25: =Y25-AB25-Z25 -> 1599.72
A26: ORD-00025 | B26: CUST-417 | C26: REP-17 | D26: Maria Garcia | E26: Maria | F26: Garcia | G26: 45228 | H26: =YEAR(G26) -> 2023 | I26: =TEXT(G26,"mmmm") -> October | J26: =TEXT(G26,"dddd") -> Sunday | K26: 0.34409722 | L26: =HOUR(K26) -> 8 | M26: =MINUTE(K26) -> 15 | N26: =SECOND(K26) -> 30 | O26: Smartwatch | P26: Wearables | Q26: 2 | R26: 273.48 | S26: =VLOOKUP(O26,'Product-cost'!A:B,2,) -> 150 | T26: Africa | U26: mariagarcia@techgadgetsco.com | W26: neutral | X26: =R26*Q26 -> 546.96 | Y26: =S26*Q26 -> 300 | Z26: =VLOOKUP(T26,Taxrate!A:B,2,FALSE) -> 0.12 | AA26: =X26*Z26 -> 65.6352 | AB26: =VLOOKUP('Sales Dataset'!O26,'Discount Rate'!A:B,2,) -> 0.07 | AC26: =Y26*AB26 -> 21 | AD26: =Y26-AB26-Z26 -> 299.81
A27: ORD-00026 | B27: CUST-981 | C27: REP-13 | D27: Ahmed Khan | E27: Ahmed | F27: Khan | G27: 45375 | H27: =YEAR(G27) -> 2024 | I27: =TEXT(G27,"mmmm") -> March | J27: =TEXT(G27,"dddd") -> Sunday | K27: 0.86427083 | L27: =HOUR(K27) -> 20 | M27: =MINUTE(K27) -> 44 | N27: =SECOND(K27) -> 33 | O27: Headphones | P27: Audio | Q27: 7 | R27: 183.63 | S27: =VLOOKUP(O27,'Product-cost'!A:B,2,) -> 50 | T27: South America | U27: ahmedkhan@sales.techg.com | V27: Great Product | W27: positive | X27: =R27*Q27 -> 1285.41 | Y27: =S27*Q27 -> 350 | Z27: =VLOOKUP(T27,Taxrate!A:B,2,FALSE) -> 0.15 | AA27: =X27*Z27 -> 192.8115 | AB27: =VLOOKUP('Sales Dataset'!O27,'Discount Rate'!A:B,2,) -> 0.03 | AC27: =Y27*AB27 -> 10.5 | AD27: =Y27-AB27-Z27 -> 349.82
A28: ORD-00027 | B28: CUST-836 | C28: REP-32 | D28: Maria Garcia | E28: Maria | F28: Garcia | G28: 46049 | H28: =YEAR(G28) -> 2026 | I28: =TEXT(G28,"mmmm") -> January | J28: =TEXT(G28,"dddd") -> Tuesday | K28: 0.44994213 | L28: =HOUR(K28) -> 10 | M28: =MINUTE(K28) -> 47 | N28: =SECOND(K28) -> 55 | O28: Headphones | P28: Audio | Q28: 13 | R28: 167.82 | S28: =VLOOKUP(O28,'Product-cost'!A:B,2,) -> 50 | T28: Africa | U28: mariagarcia@techgadgetsco.com | W28: neutral | X28: =R28*Q28 -> 2181.66 | Y28: =S28*Q28 -> 650 | Z28: =VLOOKUP(T28,Taxrate!A:B,2,FALSE) -> 0.12 | AA28: =X28*Z28 -> 261.7992 | AB28: =VLOOKUP('Sales Dataset'!O28,'Discount Rate'!A:B,2,) -> 0.03 | AC28: =Y28*AB28 -> 19.5 | AD28: =Y28-AB28-Z28 -> 649.85
A29: ORD-00028 | B29: CUST-182 | C29: REP-14 | D29: Maria Garcia | E29: Maria | F29: Garcia | G29: 45400 | H29: =YEAR(G29) -> 2024 | I29: =TEXT(G29,"mmmm") -> April | J29: =TEXT(G29,"dddd") -> Thursday | K29: 0.7984375 | L29: =HOUR(K29) -> 19 | M29: =MINUTE(K29) -> 9 | N29: =SECOND(K29) -> 45 | O29: Smartphone | P29: Mobile Devices | Q29: 7 | R29: 642.78 | S29: =VLOOKUP(O29,'Product-cost'!A:B,2,) -> 300 | T29: South America | U29: mariagarcia@techgadgetsco.com | V29: Excellent Quality | W29: positive | X29: =R29*Q29 -> 4499.46 | Y29: =S29*Q29 -> 2100 | Z29: =VLOOKUP(T29,Taxrate!A:B,2,FALSE) -> 0.15 | AA29: =X29*Z29 -> 674.919 | AB29: =VLOOKUP('Sales Dataset'!O29,'Discount Rate'!A:B,2,) -> 0.1 | AC29: =Y29*AB29 -> 210 | AD29: =Y29-AB29-Z29 -> 2099.75
A30: ORD-00029 | B30: CUST-106 | C30: REP-22 | D30: Fatima Adebayo | E30: Fatima | F30: Adebayo | G30: 45903 | H30: =YEAR(G30) -> 2025 | I30: =TEXT(G30,"mmmm") -> September | J30: =TEXT(G30,"dddd") -> Wednesday | K30: 0.69984954 | L30: =HOUR(K30) -> 16 | M30: =MINUTE(K30) -> 47 | N30: =SECOND(K30) -> 47 | O30: Smartwatch | P30: Wearables | Q30: 15 | R30: 200.14 | S30: =VLOOKUP(O30,'Product-cost'!A:B,2,) -> 150 | T30: South America | U30: fatimaadebayo@sales.techg.com | V30: Highly Recommend | W30: positive | X30: =R30*Q30 -> 3002.1 | Y30: =S30*Q30 -> 2250 | Z30: =VLOOKUP(T30,Taxrate!A:B,2,FALSE) -> 0.15 | AA30: =X30*Z30 -> 450.315 | AB30: =VLOOKUP('Sales Dataset'!O30,'Discount Rate'!A:B,2,) -> 0.07 | AC30: =Y30*AB30 -> 157.5 | AD30: =Y30-AB30-Z30 -> 2249.78
A31: ORD-00030 | B31: CUST-737 | C31: REP-33 | D31: Ahmed Khan | E31: Ahmed | F31: Khan | G31: 45733 | H31: =YEAR(G31) -> 2025 | I31: =TEXT(G31,"mmmm") -> March | J31: =TEXT(G31,"dddd") -> Monday | K31: 0.40378472 | L31: =HOUR(K31) -> 9 | M31: =MINUTE(K31) -> 41 | N31: =SECOND(K31) -> 27 | O31: Smartphone | P31: Mobile Devices | Q31: 3 | R31: 500 | S31: =VLOOKUP(O31,'Product-cost'!A:B,2,) -> 300 | T31: South America | U31: ahmedkhan@sales.techg.com | V31: Highly Recommend | W31: positive | X31: =R31*Q31 -> 1500 | Y31: =S31*Q31 -> 900 | Z31: =VLOOKUP(T31,Taxrate!A:B,2,FALSE) -> 0.15 | AA31: =X31*Z31 -> 225 | AB31: =VLOOKUP('Sales Dataset'!O31,'Discount Rate'!A:B,2,) -> 0.1 | AC31: =Y31*AB31 -> 90 | AD31: =Y31-AB31-Z31 -> 899.75
A32: ORD-00031 | B32: CUST-954 | C32: REP-12 | D32: Olivia Patel | E32: Olivia | F32: Patel | G32: 45171 | H32: =YEAR(G32) -> 2023 | I32: =TEXT(G32,"mmmm") -> September | J32: =TEXT(G32,"dddd") -> Saturday | K32: 0.55186343 | L32: =HOUR(K32) -> 13 | M32: =MINUTE(K32) -> 14 | N32: =SECOND(K32) -> 41 | O32: Laptop | P32: Computers | Q32: 11 | R32: 500 | S32: =VLOOKUP(O32,'Product-cost'!A:B,2,) -> 600 | T32: North America | U32: oliviapatel@tg.inc | V32: A Bit Expensive But Worth It | W32: neutral | X32: =R32*Q32 -> 5500 | Y32: =S32*Q32 -> 6600 | Z32: =VLOOKUP(T32,Taxrate!A:B,2,FALSE) -> 0.07 | AA32: =X32*Z32 -> 385 | AB32: =VLOOKUP('Sales Dataset'!O32,'Discount Rate'!A:B,2,) -> 0.05 | AC32: =Y32*AB32 -> 330 | AD32: =Y32-AB32-Z32 -> 6599.88
A33: ORD-00032 | B33: CUST-323 | C33: REP-28 | D33: Maria Garcia | E33: Maria | F33: Garcia | G33: 45682 | H33: =YEAR(G33) -> 2025 | I33: =TEXT(G33,"mmmm") -> January | J33: =TEXT(G33,"dddd") -> Saturday | K33: 0.7352662 | L33: =HOUR(K33) -> 17 | M33: =MINUTE(K33) -> 38 | N33: =SECOND(K33) -> 47 | O33: Laptop | P33: Computers | Q33: 3 | R33: 854.05 | S33: =VLOOKUP(O33,'Product-cost'!A:B,2,) -> 600 | T33: North America | U33: mariagarcia@tg.inc | V33: Highly Recommend | W33: positive | X33: =R33*Q33 -> 2562.15 | Y33: =S33*Q33 -> 1800 | Z33: =VLOOKUP(T33,Taxrate!A:B,2,FALSE) -> 0.07 | AA33: =X33*Z33 -> 179.3505 | AB33: =VLOOKUP('Sales Dataset'!O33,'Discount Rate'!A:B,2,) -> 0.05 | AC33: =Y33*AB33 -> 90 | AD33: =Y33-AB33-Z33 -> 1799.88
A34: ORD-00033 | B34: CUST-807 | C34: REP-17 | D34: Maria Garcia | E34: Maria | F34: Garcia | G34: 46354 | H34: =YEAR(G34) -> 2026 | I34: =TEXT(G34,"mmmm") -> November | J34: =TEXT(G34,"dddd") -> Saturday | K34: 0.90530093 | L34: =HOUR(K34) -> 21 | M34: =MINUTE(K34) -> 43 | N34: =SECOND(K34) -> 38 | O34: Laptop | P34: Computers | Q34: 10 | R34: 973.6 | S34: =VLOOKUP(O34,'Product-cost'!A:B,2,) -> 600 | T34: South America | U34: mariagarcia@techgadgetsco.com | V34: Excellent Quality | W34: positive | X34: =R34*Q34 -> 9736 | Y34: =S34*Q34 -> 6000 | Z34: =VLOOKUP(T34,Taxrate!A:B,2,FALSE) -> 0.15 | AA34: =X34*Z34 -> 1460.4 | AB34: =VLOOKUP('Sales Dataset'!O34,'Discount Rate'!A:B,2,) -> 0.05 | AC34: =Y34*AB34 -> 300 | AD34: =Y34-AB34-Z34 -> 5999.8
A35: ORD-00034 | B35: CUST-470 | C35: REP-28 | D35: Maria Garcia | E35: Maria | F35: Garcia | G35: 45936 | H35: =YEAR(G35) -> 2025 | I35: =TEXT(G35,"mmmm") -> October | J35: =TEXT(G35,"dddd") -> Monday | K35: 0.81505787 | L35: =HOUR(K35) -> 19 | M35: =MINUTE(K35) -> 33 | N35: =SECOND(K35) -> 41 | O35: Tablet | P35: Tablets | Q35: 15 | R35: 416.7 | S35: =VLOOKUP(O35,'Product-cost'!A:B,2,) -> 200 | T35: South America | U35: mariagarcia@sales.techg.com | V35: Very Satisfied | W35: positive | X35: =R35*Q35 -> 6250.5 | Y35: =S35*Q35 -> 3000 | Z35: =VLOOKUP(T35,Taxrate!A:B,2,FALSE) -> 0.15 | AA35: =X35*Z35 -> 937.575 | AB35: =VLOOKUP('Sales Dataset'!O35,'Discount Rate'!A:B,2,) -> 0.08 | AC35: =Y35*AB35 -> 240 | AD35: =Y35-AB35-Z35 -> 2999.77
A36: ORD-00035 | B36: CUST-349 | C36: REP-28 | D36: Maria Garcia | E36: Maria | F36: Garcia | G36: 45615 | H36: =YEAR(G36) -> 2024 | I36: =TEXT(G36,"mmmm") -> November | J36: =TEXT(G36,"dddd") -> Tuesday | K36: 0.66273148 | L36: =HOUR(K36) -> 15 | M36: =MINUTE(K36) -> 54 | N36: =SECOND(K36) -> 20 | O36: Smartphone | P36: Mobile Devices | Q36: 6 | R36: 582.1 | S36: =VLOOKUP(O36,'Product-cost'!A:B,2,) -> 300 | T36: Africa | U36: mariagarcia@tg.inc | W36: neutral | X36: =R36*Q36 -> 3492.6 | Y36: =S36*Q36 -> 1800 | Z36: =VLOOKUP(T36,Taxrate!A:B,2,FALSE) -> 0.12 | AA36: =X36*Z36 -> 419.112 | AB36: =VLOOKUP('Sales Dataset'!O36,'Discount Rate'!A:B,2,) -> 0.1 | AC36: =Y36*AB36 -> 180 | AD36: =Y36-AB36-Z36 -> 1799.78
A37: ORD-00036 | B37: CUST-876 | C37: REP-17 | D37: Maria Garcia | E37: Maria | F37: Garcia | G37: 46249 | H37: =YEAR(G37) -> 2026 | I37: =TEXT(G37,"mmmm") -> August | J37: =TEXT(G37,"dddd") -> Saturday | K37: 0.6597338 | L37: =HOUR(K37) -> 15 | M37: =MINUTE(K37) -> 50 | N37: =SECOND(K37) -> 1 | O37: Laptop | P37: Computers | Q37: 7 | R37: 953.1 | S37: =VLOOKUP(O37,'Product-cost'!A:B,2,) -> 600 | T37: Africa | U37: mariagarcia@tg.inc | V37: Great Product | W37: positive | X37: =R37*Q37 -> 6671.7 | Y37: =S37*Q37 -> 4200 | Z37: =VLOOKUP(T37,Taxrate!A:B,2,FALSE) -> 0.12 | AA37: =X37*Z37 -> 800.604 | AB37: =VLOOKUP('Sales Dataset'!O37,'Discount Rate'!A:B,2,) -> 0.05 | AC37: =Y37*AB37 -> 210 | AD37: =Y37-AB37-Z37 -> 4199.83
A38: ORD-00037 | B38: CUST-336 | C38: REP-13 | D38: Ahmed Khan | E38: Ahmed | F38: Khan | G38: 45514 | H38: =YEAR(G38) -> 2024 | I38: =TEXT(G38,"mmmm") -> August | J38: =TEXT(G38,"dddd") -> Saturday | K38: 0.81583333 | L38: =HOUR(K38) -> 19 | M38: =MINUTE(K38) -> 34 | N38: =SECOND(K38) -> 48 | O38: Smartphone | P38: Mobile Devices | Q38: 12 | R38: 697.38 | S38: =VLOOKUP(O38,'Product-cost'!A:B,2,) -> 300 | T38: Africa | U38: ahmedkhan@tg.inc | W38: neutral | X38: =R38*Q38 -> 8368.56 | Y38: =S38*Q38 -> 3600 | Z38: =VLOOKUP(T38,Taxrate!A:B,2,FALSE) -> 0.12 | AA38: =X38*Z38 -> 1004.2272 | AB38: =VLOOKUP('Sales Dataset'!O38,'Discount Rate'!A:B,2,) -> 0.1 | AC38: =Y38*AB38 -> 360 | AD38: =Y38-AB38-Z38 -> 3599.78
A39: ORD-00038 | B39: CUST-646 | C39: REP-14 | D39: Maria Garcia | E39: Maria | F39: Garcia | G39: 45020 | H39: =YEAR(G39) -> 2023 | I39: =TEXT(G39,"mmmm") -> April | J39: =TEXT(G39,"dddd") -> Tuesday | K39: 0.67967593 | L39: =HOUR(K39) -> 16 | M39: =MINUTE(K39) -> 18 | N39: =SECOND(K39) -> 44 | O39: Smartphone | P39: Mobile Devices | Q39: 13 | R39: 741.82 | S39: =VLOOKUP(O39,'Product-cost'!A:B,2,) -> 300 | T39: Africa | U39: mariagarcia@sales.techg.com | V39: Quick Shipping | W39: positive | X39: =R39*Q39 -> 9643.66 | Y39: =S39*Q39 -> 3900 | Z39: =VLOOKUP(T39,Taxrate!A:B,2,FALSE) -> 0.12 | AA39: =X39*Z39 -> 1157.2392 | AB39: =VLOOKUP('Sales Dataset'!O39,'Discount Rate'!A:B,2,) -> 0.1 | AC39: =Y39*AB39 -> 390 | AD39: =Y39-AB39-Z39 -> 3899.78
A40: ORD-00039 | B40: CUST-166 | C40: REP-23 | D40: Noah Kim | E40: Noah | F40: Kim | G40: 44932 | H40: =YEAR(G40) -> 2023 | I40: =TEXT(G40,"mmmm") -> January | J40: =TEXT(G40,"dddd") -> Friday | K40: 0.42350694 | L40: =HOUR(K40) -> 10 | M40: =MINUTE(K40) -> 9 | N40: =SECOND(K40) -> 51 | O40: Smartwatch | P40: Wearables | Q40: 2 | R40: 189.03 | S40: =VLOOKUP(O40,'Product-cost'!A:B,2,) -> 150 | T40: South America | U40: noahkim@sales.techg.com | V40: Love The Design | W40: positive | X40: =R40*Q40 -> 378.06 | Y40: =S40*Q40 -> 300 | Z40: =VLOOKUP(T40,Taxrate!A:B,2,FALSE) -> 0.15 | AA40: =X40*Z40 -> 56.709 | AB40: =VLOOKUP('Sales Dataset'!O40,'Discount Rate'!A:B,2,) -> 0.07 | AC40: =Y40*AB40 -> 21 | AD40: =Y40-AB40-Z40 -> 299.78
...

Sheet Product-cost
A1: Product | B1: Cost
A2: Laptop | B2: 600
A3: Smartphone | B3: 300
A4: Tablet | B4: 200
A5: Headphones | B5: 50
A6: Smartwatch | B6: 150

Sheet Taxrate
A1: Region | B1: TaxRate
A2: North America | B2: 0.07
A3: Europe | B3: 0.2
A4: Asia | B4: 0.1
A5: South America | B5: 0.15
A6: Africa | B6: 0.12

Sheet Discount Rate
A1: Product | B1: DiscountRate
A2: Laptop | B2: 0.05
A3: Smartphone | B3: 0.1
A4: Tablet | B4: 0.08
A5: Headphones | B5: 0.03
A6: Smartwatch | B6: 0.07
